Workbook

Sheet Summary
A1: QueryBook Provisional Patent Application — Registry
A2: Draft rev. October 8, 2026 (B), rebalanced QueryBook-first — not filed. Rows highlighted yellow on the other tabs are new in this revision.
A4: Balance by part | B4: Figures | C4: Claims | D4: Independent claims | E4: Sections | F4: Reference numerals
A5: A — Core platform | B5: =COUNTIF(Figures!C:C,A5) -> 22 | C5: =COUNTIF(Claims!B:B,A5) -> 20 | D5: =COUNTIFS(Claims!B:B,A5,Claims!C:C,"Independent") -> 4 | E5: =COUNTIF(Sections!B:B,A5) -> 8 | F5: =COUNTIF('Reference Numerals'!D:D,A5) -> 123
A6: B — Language & speech | B6: =COUNTIF(Figures!C:C,A6) -> 10 | C6: =COUNTIF(Claims!B:B,A6) -> 30 | D6: =COUNTIFS(Claims!B:B,A6,Claims!C:C,"Independent") -> 8 | E6: =COUNTIF(Sections!B:B,A6) -> 8 | F6: =COUNTIF('Reference Numerals'!D:D,A6) -> 124
A7: C — Identity, audit, interpretation, lecture | B7: =COUNTIF(Figures!C:C,A7) -> 8 | C7: =COUNTIF(Claims!B:B,A7) -> 32 | D7: =COUNTIFS(Claims!B:B,A7,Claims!C:C,"Independent") -> 6 | E7: =COUNTIF(Sections!B:B,A7) -> 4 | F7: =COUNTIF('Reference Numerals'!D:D,A7) -> 82
A8: D — Further embodiments & agent-era | B8: =COUNTIF(Figures!C:C,A8) -> 15 | C8: =COUNTIF(Claims!B:B,A8) -> 26 | D8: =COUNTIFS(Claims!B:B,A8,Claims!C:C,"Independent") -> 12 | E8: =COUNTIF(Sections!B:B,A8) -> 3 | F8: =COUNTIF('Reference Numerals'!D:D,A8) -> 86
A9: Total | B9: =SUM(B5:B8) -> 55 | C9: =SUM(C5:C8) -> 108 | D9: =SUM(D5:D8) -> 30 | E9: =SUM(E5:E8) -> 23 | F9: =SUM(F5:F8) -> 415
A11: New in this revision | B11: =COUNTIF(Figures!F:F,"Yes") -> 0 | C11: =COUNTIF(Claims!F:F,"Yes") -> 20 | D11: =COUNTIFS(Claims!C:C,"Independent",Claims!F:F,"Yes") -> 4 | E11: =COUNTIF(Sections!E:E,"Yes") -> 8 | F11: =COUNTIF('Reference Numerals'!E:E,"Yes") -> 123
A13: Numeral-to-figure mapping is read from the drawing labels. Numerals 100 (the LEL system as a whole) and 990–993 (translator and language-detector elements) appear in the text and key but are not labelled on any drawing; they are counted under Part B.

Sheet Reference Numerals
A1: No. | B1: Element | C1: Shown in FIG. | D1: Part | E1: New in rev. 2026-10-08 (B)
A2: 100 | B2: QueryBook LEL system | C2: — | D2: B — Language & speech | E2: No
A3: 110 | B3: Sub-Language Priming Layer (SLPL) | C3: 23 | D3: B — Language & speech | E3: No
A4: 120 | B4: Language Expression Layer (LEL) | C4: 23 | D4: B — Language & speech | E4: No
A5: 130 | B5: Transition Gate | C5: 23 | D5: B — Language & speech | E5: No
A6: 140 | B6: Phase Two semantic-communicative learning | C6: 23 | D6: B — Language & speech | E6: No
A7: 150 | B7: Multilingual Delta Acquisition module | C7: 23 | D7: B — Language & speech | E7: No
A8: 160 | B8: Speech Output Pipeline | C8: 23 | D8: B — Language & speech | E8: No
A9: 165 | B9: natural speech output | C9: 23 | D9: B — Language & speech | E9: No
A10: 170 | B10: co-grounding interface | C10: 23 | D10: B — Language & speech | E10: No
A11: 180 | B11: Federated Query Language (FQL) | C11: 23 | D11: B — Language & speech | E11: No
A12: 190 | B12: Universal Federated Connectivity System (UFCS) | C12: 23 | D12: B — Language & speech | E12: No
... A416: 8210 | B416: query result | C416: 22 | D416: A — Core platform | E416: Yes

Sheet Figures
A1: FIG. | B1: Title | C1: Part | D1: Numerals shown | E1: Numeral count | F1: New in rev. 2026-10-08 (B)
A2: 1 | B2: QueryBook system architecture (Prime Directive as Domain 0) | C2: A — Core platform | D2: 6100, 6102, 6104, 6106, 6108, 6110, 6112 | E2: =IF(LEN(TRIM(D2))=0,0,LEN(D2)-LEN(SUBSTITUTE(D2,",",""))+1) -> 7 | F2: No
A3: 2 | B3: Fact Unit — atom, envelope, and content-derived identity | C3: A — Core platform | D3: 6200, 6202, 6204, 6206, 6208, 6210, 6212, 6214, 6216, 6218 | E3: =IF(LEN(TRIM(D3))=0,0,LEN(D3)-LEN(SUBSTITUTE(D3,",",""))+1) -> 10 | F3: No
A4: 3 | B4: Fact-certification authority hierarchy | C4: A — Core platform | D4: 6300, 6302 | E4: =IF(LEN(TRIM(D4))=0,0,LEN(D4)-LEN(SUBSTITUTE(D4,",",""))+1) -> 2 | F4: No
A5: 4 | B5: UFCS substrate — three-store architecture | C5: A — Core platform | D5: 6402, 6404, 6406, 6408 | E5: =IF(LEN(TRIM(D5))=0,0,LEN(D5)-LEN(SUBSTITUTE(D5,",",""))+1) -> 4 | F5: No
A6: 5 | B6: Authored tour and exhibition sequencing | C6: A — Core platform | D6: 6500, 6501, 6502, 6503, 6504, 6510, 6512 | E6: =IF(LEN(TRIM(D6))=0,0,LEN(D6)-LEN(SUBSTITUTE(D6,",",""))+1) -> 7 | F6: No
A7: 6 | B7: FQL — joint structure and trust execution | C7: A — Core platform | D7: 6600, 6602, 6604, 6606, 6608, 6610 | E7: =IF(LEN(TRIM(D7))=0,0,LEN(D7)-LEN(SUBSTITUTE(D7,",",""))+1) -> 6 | F7: No
A8: 7 | B8: Verifying machine-generated text against certified records | C8: A — Core platform | D8: 6700, 6702, 6704, 6706, 6708 | E8: =IF(LEN(TRIM(D8))=0,0,LEN(D8)-LEN(SUBSTITUTE(D8,",",""))+1) -> 5 | F8: No
A9: 8 | B9: Federation — cross-boundary re-validation | C9: A — Core platform | D9: 6800, 6802, 6804, 6806 | E9: =IF(LEN(TRIM(D9))=0,0,LEN(D9)-LEN(SUBSTITUTE(D9,",",""))+1) -> 4 | F9: No
A10: 9 | B10: Fact-level erasure by external-key destruction | C10: A — Core platform | D10: 6900, 6902, 6904, 6906 | E10: =IF(LEN(TRIM(D10))=0,0,LEN(D10)-LEN(SUBSTITUTE(D10,",",""))+1) -> 4 | F10: No
A11: 10 | B11: Universal security architecture | C11: A — Core platform | D11: 7000, 7002, 7004 | E11: =IF(LEN(TRIM(D11))=0,0,LEN(D11)-LEN(SUBSTITUTE(D11,",",""))+1) -> 3 | F11: No
A12: 11 | B12: Universal honeypot saturation and data firehose | C12: A — Core platform | D12: 7102, 7104, 7106 | E12: =IF(LEN(TRIM(D12))=0,0,LEN(D12)-LEN(SUBSTITUTE(D12,",",""))+1) -> 3 | F12: No
A13: 12 | B13: Deployment topologies over an invariant common layer | C13: A — Core platform | D13: 7200, 7201, 7202, 7203, 7204, 7210, 7212 | E13: =IF(LEN(TRIM(D13))=0,0,LEN(D13)-LEN(SUBSTITUTE(D13,",",""))+1) -> 7 | F13: No
... A41: 40 | B41: Lecture Query — The Forever-Linked Lecture Record and Its Querying | C41: C — Identity, audit, interpretation, lecture | D41: 1310, 1311, 1312, 1313, 1314, 1315, 1316, 1317, 1318, 1319, 1320 | E41: =IF(LEN(TRIM(D41))=0,0,LEN(D41)-LEN(SUBSTITUTE(D41,",",""))+1) -> 11 | F41: No
A42: 41 | B42: Deterministic Multilingual Acquisition Without a Generative Model | C42: D — Further embodiments & agent-era | E42: =IF(LEN(TRIM(D42))=0,0,LEN(D42)-LEN(SUBSTITUTE(D42,",",""))+1) -> 0 | F42: No
A43: 42 | B43: Dialect Parameter Clusters (DPC) — Declared, Expression-Only Modulation | C43: D — Further embodiments & agent-era | E43: =IF(LEN(TRIM(D43))=0,0,LEN(D43)-LEN(SUBSTITUTE(D43,",",""))+1) -> 0 | F43: No
A44: 43 | B44: Grounded Scene Compilation to an External Generative Media Engine | C44: D — Further embodiments & agent-era | E44: =IF(LEN(TRIM(D44))=0,0,LEN(D44)-LEN(SUBSTITUTE(D44,",",""))+1) -> 0 | F44: No
A45: 44 | B45: Key-Safe External-Service Mediation | C45: D — Further embodiments & agent-era | E45: =IF(LEN(TRIM(D45))=0,0,LEN(D45)-LEN(SUBSTITUTE(D45,",",""))+1) -> 0 | F45: No
A46: 45 | B46: Scene Reconstruction From Prose — Bounded, Silhouette-Protected | C46: D — Further embodiments & agent-era | E46: =IF(LEN(TRIM(D46))=0,0,LEN(D46)-LEN(SUBSTITUTE(D46,",",""))+1) -> 0 | F46: No
A47: 46 | B47: Modular Edition Packaging — Nested Capability Editions | C47: D — Further embodiments & agent-era | E47: =IF(LEN(TRIM(D47))=0,0,LEN(D47)-LEN(SUBSTITUTE(D47,",",""))+1) -> 0 | F47: No
A48: 47 | B48: Version-Independent, Provenance-Continuous Store | C48: D — Further embodiments & agent-era | E48: =IF(LEN(TRIM(D48))=0,0,LEN(D48)-LEN(SUBSTITUTE(D48,",",""))+1) -> 0 | F48: No
A49: 48 | B49: Cited Q&A / ChatBot Application — Citation-or-UNKNOWN End to End | C49: D — Further embodiments & agent-era | D49: 4800, 4801, 4810, 4820, 4830, 4840, 4841, 4850, 4860 | E49: =IF(LEN(TRIM(D49))=0,0,LEN(D49)-LEN(SUBSTITUTE(D49,",",""))+1) -> 9 | F49: No
A50: 49 | B50: Application and Deployment Surfaces over the Invariant Core | C50: D — Further embodiments & agent-era | D50: 4900, 4910, 4920, 4930, 4940, 4950, 4960 | E50: =IF(LEN(TRIM(D50))=0,0,LEN(D50)-LEN(SUBSTITUTE(D50,",",""))+1) -> 7 | F50: No
A51: 50 | B51: Open Claw Ingestion — Artifact Segmenter and OpenClaw Interpreter | C51: D — Further embodiments & agent-era | D51: 5000, 5010, 5020, 5025, 5040, 5050, 5051, 5052, 5053, 5060, 5070, 5080, 5090, 5095 | E51: =IF(LEN(TRIM(D51))=0,0,LEN(D51)-LEN(SUBSTITUTE(D51,",",""))+1) -> 14 | F51: No
A52: 51 | B52: On-Chain Certification — Provenance NFTs, Lineage, Revocation and Independent Verification | C52: D — Further embodiments & agent-era | D52: 5100, 5110, 5120, 5140, 5150, 5160, 5170, 5180, 5190 | E52: =IF(LEN(TRIM(D52))=0,0,LEN(D52)-LEN(SUBSTITUTE(D52,",",""))+1) -> 9 | F52: No
A53: 52 | B53: Agent Protection and Deception Layer — Gateway, Traps, Firewall, Containment and Decoy | C53: D — Further embodiments & agent-era | D53: 5200, 5210, 5220, 5230, 5231, 5232, 5233, 5234, 5240, 5241, 5250, 5260, 5261, 5270, 5280, 5290, 5295 | E53: =IF(LEN(TRIM(D53))=0,0,LEN(D53)-LEN(SUBSTITUTE(D53,",",""))+1) -> 17 | F53: No
A54: 53 | B54: Tamper-Evident Security Record — Hash Chain, Write-Once Merkle Checkpoints, Mirror and Anchor | C54: D — Further embodiments & agent-era | D54: 5300, 5310, 5320, 5330, 5340, 5350, 5360, 5370 | E54: =IF(LEN(TRIM(D54))=0,0,LEN(D54)-LEN(SUBSTITUTE(D54,",",""))+1) -> 8 | F54: No
A55: 54 | B55: Agent Interoperability — MCP Tool Server and OpenClaw Skill Through the Agent Gateway | C55: D — Further embodiments & agent-era | D55: 5220, 5400, 5410, 5420, 5430, 5440, 5450, 5460, 5470 | E55: =IF(LEN(TRIM(D55))=0,0,LEN(D55)-LEN(SUBSTITUTE(D55,",",""))+1) -> 9 | F55: No
A56: 55 | B56: Hybrid Transport — Framed UFCS-FQL Messages on Priority Lanes over TCP/IP (extends FIG. 17) | C56: D — Further embodiments & agent-era | D56: 5500, 5510, 5520, 5521, 5522, 5523, 5524, 5525, 5530, 5531, 5532, 5541, 5543, 5550 | E56: =IF(LEN(TRIM(D56))=0,0,LEN(D56)-LEN(SUBSTITUTE(D56,",",""))+1) -> 14 | F56: No

Sheet Claims
A1: Claim | B1: Part | C1: Type | D1: Depends on | E1: Claim text | F1: New in rev. 2026-10-08 (B)
A2: 1 | B2: A — Core platform | C2: Independent | D2: — | E2: A computer-implemented knowledge and query system, comprising one or more processors and memory storing: a knowledge substrate of Fact Units, each Fact Unit encoding exactly one assertion as a nucleus comprising a subject, a predicate, an object and a polarity, and an envelope carrying a confidence, a provenance reference into an append-only provenance ledger, a certification by an issuing authority, a temporal anchor, and a safety classification and access-control list carried within the Fact Unit, each Fact Unit being immutable once sealed and identified by an identifier derived from its content; a query engine configured to execute a query combining a structural pattern over subjects, predicates and objects with a trust threshold, evaluating structure and certification together during traversal, and returning results bound to a response provenance value identifying the contributing Fact Units; a grounded-generation stage configured to compose a natural-language response only from Fact Units returned by the query engine, citing each contributing Fact Unit, and to return an indication that the answer is unknown where no Fact Unit satisfying the trust threshold exists; and a safety plane configured to gate every query answer, generated output and scheduled action of the system, a denial by the safety plane returning information the requester is entitled to receive. | F2: Yes
A3: 2 | B3: A — Core platform | C3: Dependent | D3: 1 | E3: The system of claim 1, wherein said identifier comprises a semantic fingerprint computed by a cryptographic hash over a normalized form of the subject, predicate, object and polarity, such that two Fact Units asserting the same assertion, including in different natural languages, carry the same fingerprint and are de-duplicated, corroborated or detected as contradictory at ingestion. | F3: Yes
A4: 3 | B4: A — Core platform | C4: Dependent | D4: 1 | E4: The system of claim 1, wherein the confidence comprises a first parameter accumulating supporting evidence and a second parameter accumulating contradicting evidence, a score equal to the ratio of the first parameter to the sum of the parameters, a credible interval, a source-diversity measure over registered source classes, a temporal decay that widens the credible interval while preserving the score, and a trend indicating whether the confidence is ascending, stable or descending. | F4: Yes
A5: 4 | B5: A — Core platform | C5: Dependent | D5: 1 | E5: The system of claim 1, wherein each certification is issued under an authority hierarchy descending from a root trust anchor, each authority class imposing a trust ceiling inherited by the Fact Units it certifies. | F5: Yes
A6: 5 | B6: A — Core platform | C6: Dependent | D6: 1 | E6: The system of claim 1, wherein the knowledge substrate comprises a fact graph whose nodes are Fact Units joined by typed edges, an ontology mesh binding subjects and predicates to canonical language-neutral identifiers, and said provenance ledger, every node and edge being keyed by content fingerprint, and a relation among more than two Fact Units being held as a single hyperedge. | F6: Yes
A7: 6 | B7: A — Core platform | C7: Dependent | D7: 1 | E7: The system of claim 1, wherein the query engine propagates trust from contributing sources, prunes a candidate falling below the trust threshold during traversal, excludes Fact Units in unresolved contradiction, and ranks the results by trust. | F7: Yes
A8: 7 | B8: A — Core platform | C8: Dependent | D8: 1 | E8: The system of claim 1, further comprising a verifier configured to extract each assertion from machine-generated text and to classify it, before the text is delivered to a reader, as verified where its fingerprint matches a certified Fact Unit, as contradicted where a certified Fact Unit has the same subject and predicate and a different object, the verifier citing the higher-trust Fact Unit, and as unknown where no candidate Fact Unit exists. | F8: Yes
A9: 8 | B9: A — Core platform | C9: Dependent | D9: 1 | E9: The system of claim 1, further comprising a federation interface by which a Fact Unit certified in a first domain is admitted into a second domain only after the second domain re-validates its signature and its trust against the second domain’s authority ceilings. | F9: Yes
A10: 9 | B10: A — Core platform | C10: Dependent | D10: 1 | E10: The system of claim 1, wherein a payload of a sealed Fact Unit is encrypted under a key held outside the system, and the Fact Unit is erased by destroying said key while the content-addressed store otherwise remains append-only. | F10: Yes
A11: 10 | B11: A — Core platform | C11: Dependent | D11: 1 | E11: The system of claim 1, wherein each Fact Unit is serialized as a packet comprising a header, the nucleus, the semantic fingerprint, the confidence, its sources, the certification, temporal fields, the provenance reference with a digital signature, safety fields and typed links, and wherein packets are appended to content-addressed blocks under a fingerprint index such that a Fact Unit having an identical fingerprint is stored once. | F11: Yes
A12: 11 | B12: A — Core platform | C12: Dependent | D12: 1 | E12: The system of claim 1, wherein the safety plane is a domain penetrating every other domain of the system and owns a transfer matrix governing each permitted movement of data between domains and a path-separation invariant, and wherein a rule prohibits withholding information a requester is entitled to receive as a means of avoiding a harm determination. | F12: Yes
A13: 12 | B13: A — Core platform | C13: Dependent | D13: 1 | E13: The system of claim 1, further comprising an adaptive response engine configured to analyze a result set, resolve a profile of the requester, assemble a response directive and a vocabulary constraint limited to terms traceable to the contributing Fact Units, and fix the directive before generation begins, generation proceeding under the directive without renegotiation. | F13: Yes
A14: 13 | B14: A — Core platform | C14: Dependent | D14: 1 | E14: The system of claim 1, wherein the grounded-generation stage renders a response in any of a plurality of natural languages directly from the same language-independent Fact Units, without per-language re-ingestion and without translating a previously generated response, each rendering being subject to the same citation requirement. | F14: Yes
... A18: 17 | B18: A — Core platform | C18: Dependent | D18: 1 | E18: The system of claim 1, further comprising a convergence layer configured to resolve a candidate set of Fact Units to a stable configuration by a deterministic iterative update that monotonically decreases an energy over the configuration, the number of stored configurations being held below a capacity ceiling, and no value being sampled. | F18: Yes
A19: 18 | B19: A — Core platform | C19: Independent | D19: — | E19: A computer-implemented method of answering a query, comprising: receiving a query expressed in a natural language; resolving the query to canonical subject and predicate identifiers; executing, over a store of immutable Fact Units each encoding one assertion and carrying a content-derived fingerprint, a confidence, a certification, a provenance reference and an in-record safety classification, a query that combines a structural pattern with a trust threshold during traversal; composing an answer only from the Fact Units returned, with a citation to each contributing Fact Unit and a provenance value binding the answer to those Fact Units; returning an indication that the answer is unknown where no Fact Unit satisfies the query; and rendering the answer in the natural language of the query, every step being gated by a safety plane that governs every output of the system. | F19: Yes
A20: 19 | B20: A — Core platform | C20: Independent | D20: — | E20: A computer-implemented method of governing machine-generated content, comprising: receiving text generated by a generative process; extracting from the text a plurality of assertions; for each assertion, computing a language-independent semantic fingerprint over a normalized subject, predicate, object and polarity of the assertion; classifying the assertion as verified where the fingerprint matches a certified Fact Unit, as contradicted where a certified Fact Unit has the same subject and predicate and a different object, and as unknown otherwise; and delivering the text to a reader only together with said classifications and, for each contradicted assertion, a citation to the contradicting Fact Unit having the higher trust. | F20: Yes
A21: 20 | B21: A — Core platform | C21: Independent | D21: — | E21: A non-transitory computer-readable medium storing instructions which, when executed by one or more processors, cause the one or more processors to perform the method of claim 18. | F21: Yes
A22: 21 | B22: B — Language & speech | C22: Independent | D22: — | E22: A computer-implemented system for hierarchical developmental language acquisition, comprising: a sub-language priming module configured to establish acoustic phonetic discrimination, phonemic awareness, prosodic sensitivity, communication-science foundations, information-theoretic signal weighting, and neurolinguistic chunking in a machine learning model prior to language corpus training; a Language Expression Layer (LEL) comprising a trained neural model configured to acquire, as internalized learned parameters, linguistic capabilities including phonetics, phonology, morphology, grammar, syntax, semantics, idiomatic expressions, and pronunciation across one or more languages from a training corpus, without reliance on external dictionaries, rule-based grammar modules, pronunciation databases, or language packs; and a transition gate mechanism configured to enforce a two-phase learning sequence in which a first phase of structural-acoustic learning completes and four readiness thresholds are satisfied before a second phase of semantic and communicative learning commences. | F22: No
A23: 22 | B23: B — Language & speech | C23: Dependent | D23: 21 | E23: The system of claim 21, wherein the four thresholds comprise: a phonemic inventory completeness threshold measuring reliable discrimination of phonemically contrastive signals; a lexical stability threshold measuring consistent word-sound identification across varying acoustic conditions; a co-occurrence density threshold measuring accumulation of sound-context pairings sufficient for statistical grounding; and a pattern saturation threshold measuring diminishing novel structural-pattern discovery. | F23: No
A24: 23 | B24: B — Language & speech | C24: Dependent | D24: 21 | E24: The system of claim 21, wherein the training corpus comprises multilingual text, phonetic data and transcriptions, pronunciation patterns, grammar structures, semantic alignment datasets, speech corpora, grapheme-to-phoneme mappings, phonology datasets, and multimedia sources comprising motion pictures, television, and dialogue recordings. | F24: No
A25: 24 | B25: B — Language & speech | C25: Dependent | D25: 21 | E25: The system of claim 21, wherein semantic alignment data within the training corpus is suppressed during the first phase and activated only upon satisfaction of all four thresholds. | F25: No
A26: 25 | B26: B — Language & speech | C26: Dependent | D26: 21 | E26: The system of claim 21, wherein during the first phase words are processed as stable acoustic objects without semantic association, and the second phase commences upon the system's derivation from the corpus that word units produce structured responses in social-interaction contexts. | F26: No
A27: 26 | B27: B — Language & speech | C27: Independent | D27: — | E27: A computer-implemented method for accelerated multilingual language acquisition comprising: acquiring a first language (L1) through a complete developmental sequence comprising sub-language priming, structural-acoustic learning, transition-gate evaluation, and semantic-communicative learning; establishing from L1 a foundation comprising phonemic discrimination, prosodic sensitivity, morphological awareness, communicative understanding, grammatical meta-knowledge, and a semantic concept inventory; upon initiating a second language (L2), identifying a delta comprising phonemic, grammatical, morphological, and semantic elements present in L2 but absent from L1; and acquiring the delta while reusing the L1 foundation for transferable elements, thereby accelerating L2 acquisition relative to L1. | F27: No
A28: 27 | B28: B — Language & speech | C28: Dependent | D28: 26 | E28: The method of claim 26, further comprising accessing a multilingual semantic alignment dataset to identify, for each L2 lexical item, whether a corresponding concept exists in the L1 inventory, and where it exists, grounding the L2 item in the existing concept rather than constructing a new one. | F28: No
A29: 28 | B29: B — Language & speech | C29: Dependent | D29: 26 | E29: The method of claim 26, wherein acquisition of each successive language beyond L2 generally requires a smaller delta than the preceding acquisition, producing an accelerating multilingual dynamic, subject to detection and targeted retraining of negative-transfer cases between particular language pairs. | F29: No
A30: 29 | B30: B — Language & speech | C30: Dependent | D30: 26 | E30: The method of claim 26, wherein phonemes present in L2 but absent from the L1 inventory are identified and subjected to targeted phonemic retraining, while shared phonemes are transferred without retraining. | F30: No
A31: 30 | B31: B — Language & speech | C31: Independent | D31: — | E31: A computer-implemented speech output pipeline configured to produce natural acoustic speech from internalized learned parameters, comprising: a lexical selection stage selecting output word forms from an internalized lexical-semantic space without dictionary lookup; a grapheme-to-phoneme conversion stage producing context-sensitive phoneme sequences from internalized mappings; a coarticulation modeling stage modifying the phoneme sequence for acoustic influence of adjacent phonemes; a prosody generation stage producing prosodic parameters at syllable, word, phrase, sentence, and discourse levels from internalized representations; a register and affect calibration stage; a self-monitoring feedback stage evaluating generated output against internalized acoustic targets and naturalness distributions and applying corrections prior to external output; and a neural vocoder stage rendering acoustic targets, prosodic contours, and affect parameters as a natural speech waveform. | F31: No
A32: 31 | B32: B — Language & speech | C32: Dependent | D32: 30 | E32: The pipeline of claim 30, wherein the coarticulation stage is trained on speech corpora and multimedia dialogue comprising naturalistic connected speech at varying rates, registers, and acoustic conditions. | F32: No
A33: 32 | B33: B — Language & speech | C33: Dependent | D33: 30 | E33: The pipeline of claim 30, wherein prosody generation at all five levels is derived exclusively from internalized representations, without a rule-based prosody system. | F33: No
A34: 33 | B34: B — Language & speech | C34: Dependent | D34: 30 | E34: The pipeline of claim 30, wherein the self-monitoring stage is an internal closed feedback loop executing prior to any external output. | F34: No
A35: 34 | B35: B — Language & speech | C35: Independent | D35: — | E35: A system for co-grounded integration of natural-language understanding with federated data query execution, comprising: a Language Expression Layer performing lexical, morphological, syntactic, and semantic analysis of natural-language input in any supported language; a Federated Query Language (FQL) interface resolving LEL semantic representations to FQL operations against a Universal Federated Connectivity System (UFCS); a UFCS executing FQL queries across federated sources and returning structured results; and a rendering pathway rendering results as natural-language output in the language of the original input, optionally via a speech output pipeline. | F35: No
A36: 35 | B36: B — Language & speech | C36: Dependent | D36: 34 | E36: The system of claim 34, wherein natural-language input in any supported language resolves to an equivalent FQL operation, such that the FQL execution layer is language-agnostic and returns equivalent results regardless of input language. | F36: No
A37: 36 | B37: B — Language & speech | C37: Dependent | D37: 34 | E37: The system of claim 34, wherein the co-grounding comprises a structural correspondence between LEL linguistic representations grounded in entities, relationships, and events and FQL formal representations of entities, relationships, and operations, said correspondence realized as a hybrid of an emergent consequence of the developmental learning sequence and an explicit semantic-alignment mapping layer. | F37: No
A38: 37 | B38: B — Language & speech | C38: Dependent | D38: 34 | E38: The system of claim 34, wherein the LEL acquires all linguistic capabilities as internalized learned parameters without external dictionaries, rule-based modules, or language packs, such that natural-language understanding is fully self-contained within the LEL model. | F38: No
A39: 38 | B39: B — Language & speech | C39: Dependent | D39: 21 | E39: The system of claim 21, further comprising the speech output pipeline of claim 30, driven exclusively by learned parameters internalized within the LEL. | F39: No
A40: 39 | B40: B — Language & speech | C40: Dependent | D40: 21 | E40: The system of claim 21, further comprising the co-grounded integration system of claim 34, wherein the LEL serves as the shared neural foundation for both language acquisition and natural-language query resolution. | F40: No
A41: 40 | B41: B — Language & speech | C41: Dependent | D41: 26 | E41: The system implementing the method of claim 26, wherein multilingual L2+ acquisition extends the language-agnostic query layer of claim 34 to each acquired language without modification of the FQL or UFCS architecture. | F41: No
A42: 41 | B42: B — Language & speech | C42: Independent | D42: — | E42: A computer-implemented pronunciation subsystem comprising: a selector configured to determine, for a supplied word or phrase in a selected language, whether a phonemizer component is available; a phonemizer path that, when the phonemizer is available, obtains a phonemic transcription therefrom; a rule path comprising, for each of a plurality of languages, an ordered set of longest-match grapheme-to-phoneme rules that, when the phonemizer is unavailable, produces an approximate phonemic transcription; and a derivation stage producing a syllable count and a primary-stress position from the transcription; wherein, when neither the phonemizer nor a rule set is available for the selected language, the subsystem returns an explicit null result and does not fabricate a transcription, such that a deterministic transcription is produced offline without any installed engine whenever a rule set exists. | F42: No
A43: 42 | B43: B — Language & speech | C43: Dependent | D43: 41 | E43: The subsystem of claim 41, wherein phonemizer invocations are memoized in a cache and bounded by a timeout such that no invocation blocks an interactive interface, and the syllable count is derived from vowel nuclei of the transcription and the primary-stress position from stress marks of the phonemizer or, for the rule path, from a per-language stress rule. | F43: No
...

Sheet Sections
A1: Section | B1: Part | C1: Paragraphs | D1: Figures | E1: New in rev. 2026-10-08 (B)
A2: Section I — System Architecture and the Prime Directive (FIG. 1) | B2: A — Core platform | C2: [0007]–[0010] | D2: FIG. 1 | E2: Yes
A3: Section II — The Fact Unit (FIG. 2, FIG. 19) | B3: A — Core platform | C3: [0011]–[0015] | D3: FIG. 2, FIG. 19 | E3: Yes
A4: Section III — The UFCS Substrate and Record Format (FIG. 4, FIG. 20, FIG. 21) | B4: A — Core platform | C4: [0016]–[0018] | D4: FIG. 4, FIG. 20, FIG. 21 | E4: Yes
A5: Section IV — Certification and the Federated Query Language (FIG. 3, FIG. 6, FIG. 22) | B5: A — Core platform | C5: [0019]–[0022] | D5: FIG. 3, FIG. 6, FIG. 22 | E5: Yes
A6: Section V — Verification and Grounded Response Generation (FIG. 7, FIG. 13) | B6: A — Core platform | C6: [0023]–[0025] | D6: FIG. 7, FIG. 13 | E6: Yes
A7: Section VI — Federation and Fact-Level Erasure (FIG. 8, FIG. 9) | B7: A — Core platform | C7: [0026]–[0027] | D7: FIG. 8, FIG. 9 | E7: Yes
A8: Section VII — Governed Agents, Security, Deployment and Application Surfaces (FIG. 10–FIG. 12, FIG. 14, FIG. 48, FIG. 49) | B8: A — Core platform | C8: [0028]–[0032] | D8: FIG. 10–FIG. 12, FIG. 14, FIG. 48, FIG. 49 | E8: Yes
A9: Section VIII — Language Independence, Transport, Media, Presentation and the Cognitive Layer (FIG. 5, FIG. 15–FIG. 18) | B9: A — Core platform | C9: [0033]–[0038] | D9: FIG. 5, FIG. 15–FIG. 18 | E9: Yes
A10: Section IX — The Sub-Language Priming Layer (SLPL) (FIG. 24) | B10: B — Language & speech | C10: [0039]–[0040] | D10: FIG. 24 | E10: No
A11: Section X — The Language Expression Layer (LEL) (FIG. 23) | B11: B — Language & speech | C11: [0041]–[0042] | D11: FIG. 23 | E11: No
A12: Section XI — Developmental Learning Sequence and Transition Gate (FIG. 25) | B12: B — Language & speech | C12: [0043]–[0045] | D12: FIG. 25 | E12: No
... A24: Section XXIII — Agent-Era Extensions: Arbitrary-Artifact Ingestion, On-Chain Certification, Agent Protection and Deception, Tamper-Evident Security Record, Agent Interoperability, and Framed Hybrid Transport (FIG. 50–FIG. 55) | B24: D — Further embodiments & agent-era | C24: [0081]–[0107] | D24: FIG. 50–FIG. 55 | E24: No
