Workbook

Sheet Summary v69
A1: QueryBook Composite Feature Registry v69
A2: Rows highlighted yellow on the Feature Registry sheet were added in v66 or v69 (column K). Verified Agent Transport is supported, not included: see the Supported External Services sheet. All v65 rows (columns A–G) and all v66 rows are unchanged.
A4: Measure | B4: Value
A5: Total features | B5: =COUNTA('Feature Registry v69'!A2:A383) -> 382
A6: Features carried from v65 | B6: =COUNTIF('Feature Registry v69'!K2:K383,"v65 or earlier") -> 293
A7: Features added in v66 | B7: =COUNTIF('Feature Registry v69'!K2:K383,"v66") -> 70
A8: Features added in v69 (support for agent-wrapper services, FIG. 56) | B8: =COUNTIF('Feature Registry v69'!K2:K383,"v69") -> 19
A9: External services supported (not QueryBook features) | B9: =COUNT('Supported External Services'!F2:F20) -> 2
A10: Features with a drawing reference | B10: =COUNTIF('Feature Registry v69'!H2:H383,"?*") -> 192
A11: Features with a worked expression | B11: =SUMPRODUCT(--('Feature Registry v69'!G2:G383<>"")) -> 270
A12: New features built in prototype v9.64 | B12: =COUNTIF('Feature Registry v69'!I2:I383,"Built — prototype v9.64") -> 53
A13: New features built in laboratory prototype | B13: =COUNTIF('Feature Registry v69'!I2:I383,"Built — laboratory prototype") -> 8
A14: New features specified (not yet built) | B14: =COUNTIF('Feature Registry v69'!I2:I383,"Specified") -> 28
A15: Algorithms documented | B15: =COUNTA('Algorithms (v69)'!A2:A20) -> 19
A16: Drawings (FIG. 1–56) | B16: =COUNTA('Drawings FIG 1-56'!A2:A57) -> 56
A17: Drawings referenced by at least one feature | B17: =COUNTIF('Drawings FIG 1-56'!D2:D57,">0") -> 48
A19: Features by domain | B19: All | C19: New in v66 | D19: New in v69
A20: Access, Rights & Retention | B20: =COUNTIF('Feature Registry v69'!C2:C383,A20) -> 25 | C20: =COUNTIFS('Feature Registry v69'!C2:C383,A20,'Feature Registry v69'!K2:K383,"v66") -> 6 | D20: =COUNTIFS('Feature Registry v69'!C2:C383,A20,'Feature Registry v69'!K2:K383,"v69") -> 3
A21: Authoring, Editions & Publication | B21: =COUNTIF('Feature Registry v69'!C2:C383,A21) -> 20 | C21: =COUNTIFS('Feature Registry v69'!C2:C383,A21,'Feature Registry v69'!K2:K383,"v66") -> 5 | D21: =COUNTIFS('Feature Registry v69'!C2:C383,A21,'Feature Registry v69'!K2:K383,"v69") -> 0
A22: Commerce & Entitlement Tokens | B22: =COUNTIF('Feature Registry v69'!C2:C383,A22) -> 17 | C22: =COUNTIFS('Feature Registry v69'!C2:C383,A22,'Feature Registry v69'!K2:K383,"v66") -> 1 | D22: =COUNTIFS('Feature Registry v69'!C2:C383,A22,'Feature Registry v69'!K2:K383,"v69") -> 1
A23: External Integration & Analysis | B23: =COUNTIF('Feature Registry v69'!C2:C383,A23) -> 32 | C23: =COUNTIFS('Feature Registry v69'!C2:C383,A23,'Feature Registry v69'!K2:K383,"v66") -> 11 | D23: =COUNTIFS('Feature Registry v69'!C2:C383,A23,'Feature Registry v69'!K2:K383,"v69") -> 6
A24: Grounded Expression | B24: =COUNTIF('Feature Registry v69'!C2:C383,A24) -> 21 | C24: =COUNTIFS('Feature Registry v69'!C2:C383,A24,'Feature Registry v69'!K2:K383,"v66") -> 4 | D24: =COUNTIFS('Feature Registry v69'!C2:C383,A24,'Feature Registry v69'!K2:K383,"v69") -> 0
A25: Inference, Prediction & Calibration | B25: =COUNTIF('Feature Registry v69'!C2:C383,A25) -> 35 | C25: =COUNTIFS('Feature Registry v69'!C2:C383,A25,'Feature Registry v69'!K2:K383,"v66") -> 0 | D25: =COUNTIFS('Feature Registry v69'!C2:C383,A25,'Feature Registry v69'!K2:K383,"v69") -> 1
A26: Ingestion & Sensory Intake | B26: =COUNTIF('Feature Registry v69'!C2:C383,A26) -> 35 | C26: =COUNTIFS('Feature Registry v69'!C2:C383,A26,'Feature Registry v69'!K2:K383,"v66") -> 11 | D26: =COUNTIFS('Feature Registry v69'!C2:C383,A26,'Feature Registry v69'!K2:K383,"v69") -> 1
A27: Interaction Surfaces | B27: =COUNTIF('Feature Registry v69'!C2:C383,A27) -> 26 | C27: =COUNTIFS('Feature Registry v69'!C2:C383,A27,'Feature Registry v69'!K2:K383,"v66") -> 1 | D27: =COUNTIFS('Feature Registry v69'!C2:C383,A27,'Feature Registry v69'!K2:K383,"v69") -> 0
A28: Knowledge Substrate | B28: =COUNTIF('Feature Registry v69'!C2:C383,A28) -> 19 | C28: =COUNTIFS('Feature Registry v69'!C2:C383,A28,'Feature Registry v69'!K2:K383,"v66") -> 2 | D28: =COUNTIFS('Feature Registry v69'!C2:C383,A28,'Feature Registry v69'!K2:K383,"v69") -> 2
A29: Learning & Assessment | B29: =COUNTIF('Feature Registry v69'!C2:C383,A29) -> 5 | C29: =COUNTIFS('Feature Registry v69'!C2:C383,A29,'Feature Registry v69'!K2:K383,"v66") -> 0 | D29: =COUNTIFS('Feature Registry v69'!C2:C383,A29,'Feature Registry v69'!K2:K383,"v69") -> 0
A30: Ontology & Conceptual Structure | B30: =COUNTIF('Feature Registry v69'!C2:C383,A30) -> 11 | C30: =COUNTIFS('Feature Registry v69'!C2:C383,A30,'Feature Registry v69'!K2:K383,"v66") -> 0 | D30: =COUNTIFS('Feature Registry v69'!C2:C383,A30,'Feature Registry v69'!K2:K383,"v69") -> 0
A31: Platform Governance & Evolution | B31: =COUNTIF('Feature Registry v69'!C2:C383,A31) -> 51 | C31: =COUNTIFS('Feature Registry v69'!C2:C383,A31,'Feature Registry v69'!K2:K383,"v66") -> 21 | D31: =COUNTIFS('Feature Registry v69'!C2:C383,A31,'Feature Registry v69'!K2:K383,"v69") -> 3
A32: Prime Directive | B32: =COUNTIF('Feature Registry v69'!C2:C383,A32) -> 6 | C32: =COUNTIFS('Feature Registry v69'!C2:C383,A32,'Feature Registry v69'!K2:K383,"v66") -> 0 | D32: =COUNTIFS('Feature Registry v69'!C2:C383,A32,'Feature Registry v69'!K2:K383,"v69") -> 0
A33: Retrieval & Response | B33: =COUNTIF('Feature Registry v69'!C2:C383,A33) -> 40 | C33: =COUNTIFS('Feature Registry v69'!C2:C383,A33,'Feature Registry v69'!K2:K383,"v66") -> 8 | D33: =COUNTIFS('Feature Registry v69'!C2:C383,A33,'Feature Registry v69'!K2:K383,"v69") -> 2
A34: World Model & Perception | B34: =COUNTIF('Feature Registry v69'!C2:C383,A34) -> 39 | C34: =COUNTIFS('Feature Registry v69'!C2:C383,A34,'Feature Registry v69'!K2:K383,"v66") -> 0 | D34: =COUNTIFS('Feature Registry v69'!C2:C383,A34,'Feature Registry v69'!K2:K383,"v69") -> 0

Sheet Feature Registry v69
A1: No. | B1: Feature | C1: Domain | D1: Citation | E1: Function | F1: Rule | G1: Worked expression | H1: Drawing reference (FIG.) | I1: Status | J1: Prototype module | K1: Registry version added
A2: 1 | B2: Standard Q&A | C2: Retrieval & Response | D2: §52.13.2 | E2: User-facing§52.13.2Reader Parse the query, retrieve candidate Fact Units via the Associative Recall Engine, run the Attractor Network to stabilize the candidate set, compose a response through the Narrative Graph's grounded-generation pipeline, deliver. | F2: Retrieval confidence must clear a minimum threshold before a Fact Unit is offered as grounding. | G2: =IF(0.62>=0.5,"Included as Grounding","Excluded") -> Included as Grounding | H2: 18, 48 | K2: v65 or earlier
A3: 2 | B3: Guided Exploration | C3: Retrieval & Response | D3: §52.13.2 | E3: User-facing§52.13.2Reader As Standard Q&A, but each turn's candidate retrieval is conditioned on the accumulated Cognitive Context Window from prior turns rather than the query alone. | F3: Context weight decays with turn distance; a fact from 5 turns ago counts less than one from the last turn. | G3: =1/(1+2) -> 0.33333333 | H3: 48 | K3: v65 or earlier
A4: 3 | B4: Discussion Mode | C4: Retrieval & Response | D4: §52.13.3 | E4: User-facing§52.13.3Reader / Researcher Retrieve Fact Units as in Standard Q&A; adopt a text-grounded viewpoint only where the source material's groundedness for that viewpoint clears a threshold. | F4: Viewpoint adoption is gated on a groundedness score exceeding a fixed threshold. | G4: =IF(0.8>0.6,"Adopt Viewpoint","Retrieve Only") -> Adopt Viewpoint | H4: 48 | K4: v65 or earlier
A5: 4 | B5: Tutorial Mode | C5: Retrieval & Response | D5: §52.13.2 | E5: User-facing§52.13.2Student Sequence a book's Fact Units into ordered instructional steps of increasing difficulty. | F5: Steps are ordered by a difficulty rank; a step's position is its rank among all steps. | G5: =RANK(3,{1,2,3,4,5}) -> 3 | K5: v65 or earlier
A6: 5 | B6: Comprehension Check | C6: Learning & Assessment | D6: §52.13.2 | E6: User-facing§52.13.2Student Generate a question from a target Fact Unit; compare a submitted answer's semantic similarity against that Fact Unit's content; correct if similarity clears a threshold. | F6: Answer correctness is a threshold comparison on a semantic-similarity score. | G6: =IF(0.87>=0.75,"Correct","Incorrect") -> Correct | K6: v65 or earlier
A7: 6 | B7: Semantic Exploration | C7: Retrieval & Response | D7: §52.13.2 | E7: User-facing§52.13.2Reader / Researcher Traverse the Ontology Mesh outward from a starting node, surfacing connected nodes ranked by relationship strength. | F7: Neighbors are included only above a relationship-strength threshold. | G7: =IF(0.55>=0.4,"Include Neighbor","Exclude") -> Include Neighbor | H7: 4 | K7: v65 or earlier
A8: 7 | B8: Timeline Reconstruction | C8: Retrieval & Response | D8: §52.13.2 | E8: User-facing§52.13.2Reader Extract TemporalAnchor fields from a book's Fact Units and order them chronologically. | F8: Chronological ordering is a pairwise date comparison. | G8: =IF(DATE(1848,3,14)<DATE(1849,1,1),"Event A First","Event B First") -> Event A First | K8: v65 or earlier
A9: 8 | B9: Edition Comparison | C9: Retrieval & Response | D9: §52.13.2 | E9: User-facing§52.13.2Reader Diff the VersionChain entries of two edition-tagged Fact Unit sets, surfacing additions, removals, and changes. | F9: A field differs between editions if its two values are unequal. | G9: =IF("v2 text"<>"v1 text","Changed","Same") -> Changed | K9: v65 or earlier
A10: 9 | B10: Flashcard Generation | C10: Retrieval & Response | D10: §52.13.2.1 | E10: User-facing§52.13.2.1Student Select a Fact Unit, derive a question/answer pair from its content and SupportingFactUnits, format as a citing study card. | F10: Structural rule: One flashcard derives from exactly one Fact Unit; a card spanning two Fact Units is not generated. | K10: v65 or earlier
A11: 10 | B11: Fact Graph Visualization | C11: Interaction Surfaces | D11: §52.13.2.2 | E11: User-facing§52.13.2.2Researcher Render Ontology Mesh nodes and edges for a given scope as an explicit graph structure. | F11: Structural rule: The rendered graph contains exactly the nodes and edges within the requester's scope description; no node is drawn that traversal would not return. | H11: 4 | K11: v65 or earlier
A12: 11 | B12: Inline Fact Previews | C12: Interaction Surfaces | D12: §52.13.2.2 | E12: User-facing§52.13.2.2Reader On hover/tap of a cited fact reference, retrieve and display that Fact Unit's summary without a new query round-trip. | F12: Structural rule: A preview resolves the cited Fact Unit already retrieved for the response; it issues no new query and can surface no record the response did not cite. | K12: v65 or earlier
A13: 12 | B13: Contextual Footnotes | C13: Interaction Surfaces | D13: §52.13.2.1 | E13: User-facing§52.13.2.1Reader Attach a Fact Unit's supplementary detail as an inline, dismissible footnote at its citation point. | F13: Structural rule: A footnote attaches at the citation point of the Fact Unit it elaborates and is dismissible without altering the response body. | K13: v65 or earlier
A14: 13 | B14: Personal Notes | C14: Interaction Surfaces | D14: Chapter 63 | E14: User-facingChapter 63Reader Store reader-authored text as a Fact Unit with AccessControlList restricted to the authoring reader alone. | F14: Access is granted only when the requester's identity matches the note's owner. | G14: =IF("reader_42"="reader_42","Access Granted","Denied") -> Access Granted | K14: v65 or earlier
A15: 14 | B15: Social Annotations | C15: Interaction Surfaces | D15: §52.13.2.1 | E15: User-facing§52.13.2.1 / Ch63Reader As Personal Notes, but AccessControlList defaults to author-configured sharing rather than reader-private. | F15: Visibility depends on a sharing flag rather than strict owner-match. | G15: =IF(TRUE(),"Visible to Others","Private") -> Visible to Others | K15: v65 or earlier
A16: 15 | B16: Message Boards | C16: Interaction Surfaces | D16: Chapter 64 | E16: User-facingChapter 64Reader / Author Route a post into one of four board-type partitions per the poster's role; apply moderation-action checks on write. | F16: Board partition is selected from a fixed enumeration by type index. | G16: =CHOOSE(2,"Book-Wide","Chapter","Class","Announcement") -> Chapter | K16: v65 or earlier
A17: 16 | B17: Private Messaging | C17: Access, Rights & Retention | D17: §82.2 | E17: User-facing§82.2Reader / Author Write a DirectMessage Fact Unit with AccessControlList restricted to exactly the sending and receiving identity. | F17: Access is granted only to the two identities named on the message. | G17: =IF(OR("reader_9"="reader_9","reader_9"="author_3"),"Access Granted","Denied") -> Access Granted | K17: v65 or earlier
A18: 17 | B18: Reader History Interface | C18: Access, Rights & Retention | D18: §36.8 | E18: User-facing§36.8Reader Chronological record of every session across every owned book, each entry expandable to show what was retrieved. | F18: Sessions are ordered by timestamp, most recent first. | G18: =IF(DATE(2026,8,10)>DATE(2026,8,1),"Shown First","Shown Later") -> Shown First | K18: v65 or earlier
A19: 18 | B19: Cross-Book Thematic Analysis | C19: Access, Rights & Retention | D19: Chapter 36 | E19: User-facingChapter 36Reader / Student Analyze a reader's own query-history Fact Units for recurring semantic clusters, then match against Ontology Mesh nodes in other owned books. | F19: A cross-book match requires cluster similarity above a threshold. | G19: =IF(0.71>=0.6,"Genuine Connection","No Match") -> Genuine Connection | H19: 4 | K19: v65 or earlier
A20: 19 | B20: QBQL Structured Query | C20: Retrieval & Response | D20: Chapter 18 | E20: User-facingChapter 18Researcher Parse a declarative query against the Fact Graph schema, resolve predicates, execute as a deterministic read-only traversal. | F20: Pure function of (query, current state) — no side effects. | H20: 6 | K20: v65 or earlier
A21: 20 | B21: NLPL Natural-Language Programs | C21: Retrieval & Response | D21: Chapter 48 | E21: User-facingChapter 48Researcher / Author Break the natural-language instruction into its constituent components before any code is generated. | F21: Structural rule: Decomposition into operational intents completes before any intent is bound to a concrete entity; an ambiguous binding halts compilation rather than resolving it. | K21: v65 or earlier
A22: 21 | B22: Application Library and Generator | C22: Authoring, Editions & Publication | D22: Chapter 39 | E22: User-facingChapter 39Reader Match a plain-language request against the existing template library by task/domain similarity; compose a new template only where no adequate match exists. | F22: A library match is used only above a similarity threshold; below it, composition is triggered. | G22: =IF(0.4>=0.65,"Use Existing Template","Compose New Template") -> Compose New Template | K22: v65 or earlier
A23: 22 | B23: Video Colorization & Upscaling (VCUM) | C23: Authoring, Editions & Publication | D23: Chapter 44 | E23: User-facingChapter 44Reader / Researcher Semantic Colorization Engine infers plausible color per-region from identified material class and lighting; upscaling synthesizes detail constrained to remain consistent with the source. | F23: Deterministic inference function: identical inputs always yield the identical inferred color. | H23: 16 | K23: v65 or earlier
A24: 23 | B24: Immersive 3D Scenes (IQR) | C24: Interaction Surfaces | D24: Chapter 46 | E24: User-facingChapter 46Reader Where grounding Fact Units carry sufficient spatial detail, instantiate WASM Fact Units as a renderable 3D scene. | F24: Scene rendering is triggered only once spatial-detail sufficiency clears a threshold. | G24: =IF(0.8>=0.7,"Render 3D Scene","Text Only") -> Render 3D Scene | H24: 5 | K24: v65 or earlier
A25: 24 | B25: Tour and Exhibition Mode | C25: Interaction Surfaces | D25: §46.9 | E25: User-facing§46.9Author / Reader Sequence author-selected IQR scenes into ordered Waypoints; playback steps through at reader-controlled pace. | F25: Waypoint order is a fixed sequence index. | G25: =INDEX({"Scene A","Scene B","Scene C"},2) -> Scene B | H25: 5 | K25: v65 or earlier
A26: 25 | B26: Presenter Mode | C26: Interaction Surfaces | D26: §46.10 | E26: User-facing§46.10Author Verify the requested presence mode against the author's current, mode-specific, non-revoked Author Authorization Record. | F26: Authorization is granted only if the specific mode is both authorized and not revoked. | G26: =IF(AND(TRUE(),NOT(FALSE())),"Authorized","Denied") -> Authorized | K26: v65 or earlier
A27: 26 | B27: Instructor-Created Tours | C27: Interaction Surfaces | D27: Chapter 83 | E27: User-facingChapter 83Instructor Sequence a Tour from already-published scenes, composed by an instructor rather than the author; carries non-removable ContentRole = INSTRUCTOR attribution. | F27: Attribution label is fixed by content role, not editable by the instructor. | G27: =IF("INSTRUCTOR"="INSTRUCTOR","Label: Instructor-Created","Label: Author-Curated") -> Label: Instructor-Created | H27: 5 | K27: v65 or earlier
A28: 27 | B28: Instructor Notes | C28: Interaction Surfaces | D28: §83.1 | E28: User-facing§83.1Instructor As Personal Notes, but AccessControlList is scoped to the instructor's class roster. | F28: Access is granted only to identities on the class roster. | G28: =IF(COUNTIF({"student_1","student_2","student_3"},"student_2")>0,"Access Granted","Denied") -> Access Granted | K28: v65 or earlier
A29: 28 | B29: Session Books | C29: Interaction Surfaces | D29: §84.1 | E29: User-facing§84.1Reader / Researcher Construct a delta reference over the reader's library without copying underlying Fact Units; purge on session end. | F29: The delta is a reference set, not a copy; its size is independent of the underlying library size. | K29: v65 or earlier
A30: 29 | B30: Instructor-Customized Assessment Templates | C30: Learning & Assessment | D30: §84.2 | E30: User-facing§84.2Instructor Store instructor-chosen structural parameters as a reusable template; apply structure to Comprehension Check generation while sourcing content from the Fact Graph. | F30: Question count is bounded by the template's configured maximum. | G30: =MIN(12,10) -> 10 | K30: v65 or earlier
A31: 30 | B31: Instructor Grant Visibility Dashboard | C31: Access, Rights & Retention | D31: Chapter 85 | E31: User-facingChapter 85Instructor Query all active instructor-grant Fact Units for the viewing identity; join against Class Board, Instructor Tour, and Assessment Template records. | F31: A grant is shown only while its status is active. | G31: =IF("ACTIVE"="ACTIVE","Show on Dashboard","Hide - Expired") -> Show on Dashboard | K31: v65 or earlier
A32: 31 | B32: Manuscript Upload | C32: Authoring, Editions & Publication | D32: §61.1.1 | E32: User-facing§61.1.1Author Ingest the uploaded file in a single event; tag resulting Fact Units DraftStatus = DRAFT; restrict visibility until explicit submission. | F32: Visibility is gated on DraftStatus. | G32: =IF("DRAFT"="DRAFT","Author-Only Visibility","Public") -> Author-Only Visibility | K32: v65 or earlier
A33: 32 | B33: Manuscript Editor | C33: Authoring, Editions & Publication | D33: §61.1 | E33: User-facing§61.1Author Accumulate Fact Units incrementally per edit; each edit versioned through the standard VersionChain mechanism. | F33: Each edit increments the version counter by exactly one. | G33: =3+1 -> 4 | K33: v65 or earlier
A34: 33 | B34: Narrative Coherence Checking | C34: Authoring, Editions & Publication | D34: §61.2 | E34: User-facing§61.2Author Apply Discussion Mode's critical-analysis capability to the draft's own Fact Graph, surfacing internal contradictions. | F34: A contradiction is flagged when two Fact Units assert incompatible values for the same subject/field. | G34: =IF("alive"<>"deceased","Contradiction Found","Consistent") -> Contradiction Found | H34: 7 | K34: v65 or earlier
A35: 34 | B35: Counterfactual Exploration (Drafting) | C35: Authoring, Editions & Publication | D35: §61.3 | E35: User-facing§61.3Author Construct a Scenario Graph COUNTERFACTUAL branch from the draft's current state, preserving both branches. | F35: Both counterfactual branches are preserved; branch count after divergence is two. | G35: =IF(1+1>=2,"Both branches preserved","Branch lost") -> Both branches preserved | K35: v65 or earlier
A36: 35 | B36: Supplemental Content | C36: Access, Rights & Retention | D36: §82.1 | E36: User-facing§82.1Author Ingest author-provided material, tag ContentRole = SUPPLEMENTAL, link to the parent book without altering its Rights Validation status. | F36: Rights status is read-only from the supplemental-ingestion path; it cannot be modified by this operation. | G36: =IF("VALIDATED"="VALIDATED","Rights Status Unchanged","Rights Status Unchanged") -> Rights Status Unchanged | K36: v65 or earlier
A37: 36 | B37: Multi-Author Collaboration | C37: Authoring, Editions & Publication | D37: Chapter 74 | E37: User-facingChapter 74Co-Authors Detect concurrent-write divergence via VersionChain head comparison. | F37: A conflict exists when two authors' starting version heads differ from the current head. | G37: =IF(3<>5,"Conflict Detected","No Conflict") -> Conflict Detected | K37: v65 or earlier
A38: 37 | B38: Author-Hosted Reader Events | C38: Authoring, Editions & Publication | D38: Chapter 62 | E38: User-facingChapter 62Author / Instructor Register an external collaboration platform once via the Source Connector Registry; dispatch scheduling/invitation calls through it. | F38: Structural rule: An event operation is dispatched only through a connector registered under a declared capability; the platform's broader authority does not become system authority. | K38: v65 or earlier
A39: 38 | B39: Class Boards | C39: Interaction Surfaces | D39: §64.1 | E39: User-facing§64.1Instructor / Student As Message Boards, scoped to a specific instructor + class pairing. | F39: Structural rule: Board scope is the intersection of an instructor identity and a class roster; a post is visible only within that pairing. | K39: v65 or earlier
A40: 39 | B40: Publisher Submission and Print-on-Demand | C40: Authoring, Editions & Publication | D40: Chapter 60 | E40: User-facingChapter 60Publisher / Author Accept a manuscript/title submission and route it into the publishing workflow. | F40: Structural rule: Rights validation precedes routing into the publishing workflow; an unvalidated submission does not enter it. | K40: v65 or earlier
...

Sheet Registry Record
A1: QueryBook Composite Feature Registry v65
A2: Assembled September 6, 2026, from Composite Registry v64 plus the Contextual Value Models specification, adopted as Bible v2.1 Pass 118 (§109.9) upon the inventor’s direction to specify where cultural norms, social values, ergonomics, and context are stored.
A3: Features: 293. Rows 1–279 canonical (Inventory v59). Row 280 Skill Inventory Layer (Pass 113). Rows 281–287 enhanced Fact Unit record field families (§3.8, Pass 115). Rows 288–291 record-fused encoding and database-neutral boundary (§3.9, Pass 116). Row 292 the Fact Unit Language (§3.10, Pass 117). Row 293 Contextual Value Models (§109.9, Pass 118) — registered configuration consumed by the interpretive layer, distinct from Fact Units and from World-View Model concepts. All additive.
A4: Worked expressions: 229 — unchanged.
A5: Claims: 354 (contiguous 1–354, 7 independent) — unchanged. Contextual Value Models is a where-stored specification and adds no claim; it enters Appendix A as feature 293.
A6: Additive covenant: no feature removed. Covenant floor now 293 features / 354 claims. The previously-removed mandatory external fact-transport format and external fact-query language remain removed.
A7: Canon of record: Bible v2.1 (Pass 118) · Provisional CONSOLIDATED v2.7 (Appendix A 293 features, claims 1–354) · Core Technology Overview v13 · Feature Inventory v59 · QueryBook Master Bible (Sept 1) · this Composite Registry v65.
A9: QueryBook Composite Feature Registry v66
A10: Assembled October 9, 2026, from Composite Registry v65 plus the features disclosed in Provisional Patent Application of October 9, 2026 and built in QueryBook prototype v9.64.
A11: Features: 363. Rows 1–293 carried from v65 unchanged (columns A–G). Rows 294–363 added in v66: Open Claw ingestion; on-chain certification; agent protection and deception; tamper-evident security record; agent interoperability (MCP / OpenClaw); framed hybrid transport; record-grounded colorization; the security architecture, honeypot saturation, worm defense, agent passport, post-quantum signatures and default-on-deny approval described in the application; and the October embodiments (pronunciation, speech QC, LIL, UIAS, PIL, Lecture Query, multilingual acquisition, dialects, scene director and reconstructor, key-safe mediation, editions, version-independent store, cited Q&A, deployment surfaces).
A12: New columns: H Drawing reference (FIG. 1–55 of the synchronized drawing set); I Status and J Prototype module (new rows); K Registry version added. Drawing references for v65 rows are assigned by subject and should be confirmed by counsel.
A13: New sheets: Algorithms (v66) — 13 documented algorithms with inputs, procedure, output and module; Drawings FIG 1-55 — each figure with the count of features and algorithms referencing it; Summary v66.
... A21: Status of all v69 rows: Specified — not yet built. Additive covenant: no feature removed relative to v66; no v65 cell in columns A–G altered; no v66 row altered. Claims: 357.

Sheet Algorithms (v69)
A1: ID | B1: Algorithm | C1: Features (registry) | D1: Drawing (FIG.) | E1: Inputs | F1: Procedure | G1: Output | H1: Deterministic | I1: Prototype module
A2: ALG-01 | B2: Content-based format detection | C2: Content-Based Format Detection | D2: 50 | E2: Artifact bytes | F2: 1. Read the leading bytes. 2. Match against format signatures (PDF, ZIP/OOXML, PNG, JPEG, RIFF, MP4, …). 3. For container formats, inspect internal structure (e.g. OOXML part names). 4. Fall back to text heuristics; otherwise 'unknown'. | G2: Format label | H2: Yes | I2: qb_openclaw
A3: ALG-02 | B3: Archive bomb guard | C3: Archive Expansion Bounds | D3: 50 | E3: Archive directory; bounds on depth, members, size, ratio | F3: 1. Read the archive directory without expanding. 2. Sum declared sizes, count members, compute ratio expanded/compressed, track nesting depth. 3. Refuse if any bound is exceeded. 4. Otherwise expand member by member, re-checking running totals. | G3: Expanded members or refusal | H3: Yes | I3: qb_openclaw
A4: ALG-03 | B4: Instruction-like content screen and trust floor | C4: Instruction-Like Content Screen; Untrusted-Record Trust Floor | D4: 50 | E4: Segment text (including hidden text) | F4: 1. Normalize text (case, invisible characters). 2. Match instruction-injection signatures. 3. If matched, flag the segment, set trust 0.2 (< answer threshold 0.5), record the flag in the security log. 4. Otherwise convert the segment normally. | G4: Admitted record with trust value; security-log flag | H4: Yes | I4: qb_openclaw,qb_seclog
A5: ALG-04 | B5: Certificate mint and verify | C5: Provenance Certificate Token; Independent Certificate Verifier | D5: 51 | E5: Sealed object; certificate contract address | F5: Mint: 1. Compute the object's content hash. 2. Refuse if the contract already holds a token for the hash. 3. Build metadata (kind, lineage) as an on-chain data URI. 4. Sign and send the mint transaction. Verify: 1. Recompute the hash of the held object. 2. Query the contract for the hash. 3. Report existence, holder, match, revoked, superseded. | G5: Token ID / verification report | H5: Yes | I5: qb_nft
A6: ALG-05 | B6: Deterministic transaction signing | C6: In-System Transaction Signer with Self-Test | D6: 51 | E6: Transaction fields; private key | F6: 1. At start-up, run Keccak-256, secp256k1 and RLP test vectors; disable on any failure. 2. Encode the transaction (RLP / typed). 3. Hash with Keccak-256. 4. Derive the nonce k by RFC 6979 (HMAC-DRBG). 5. Sign; normalize s to the low half-order. 6. Refuse a money-bearing chain unless elected. | G6: Signed raw transaction | H6: Yes (RFC 6979) | I6: qb_nft
A7: ALG-06 | B7: Agent Gateway admission | C7: Agent Gateway Authentication; Per-Agent Command Allow-List | D7: 52, 54 | E7: Caller ID, timestamp, keyed token, command | F7: 1. Recompute the keyed token for (caller, timestamp); compare in constant time. 2. Refuse if |now − timestamp| > 300 s or the token was seen before. 3. Refuse if the command is not on the caller's allow-list. 4. Run the deception check and firewall. 5. Record the decision. | G7: Allow / deny / isolate | H7: Yes | I7: qb_shield
A8: ALG-07 | B8: Deception trigger and isolation | C8: Honeycode; Honeytokens; Tripwires; Honeypot Agents; Impersonation-Safe Isolation Register | D8: 52 | E8: Command, parameters, connection properties | F8: 1. If the command is reserved, a honeytoken is used, a tripwire path or act is touched, or a honeypot agent is contacted: post a trigger. 2. Form the client key from the connection (loopback: address + hash of user agent). 3. Enter the key in the isolation register. 4. Route the client's further calls to the decoy and record them. | G8: Isolated session | H8: Yes | I8: qb_shield,qb_decoy
A9: ALG-08 | B9: Per-caller anomaly scoring | C9: Per-Caller Anomaly Detector | D9: 52 | E9: Per-caller request history | F9: 1. Maintain each caller's baseline rate, breadth and error pattern. 2. Score current behaviour (enumeration breadth, timing) against the baseline. 3. Post an isolation trigger above threshold. | G9: Anomaly score / trigger | H9: Yes | I9: qb_shield
A10: ALG-09 | B10: Hash-chained append and Merkle checkpoint | C10: Hash-Chained Security Record; Write-Once Signed Merkle Checkpoint | D10: 53 | E10: Security decision | F10: 1. Serialize the entry canonically. 2. h_i = SHA-256(h_{i−1} ‖ entry). 3. Every N entries: build a Merkle tree over the new entry hashes. 4. Sign root ‖ previous checkpoint hash with the deployment key (HMAC). 5. Create the checkpoint file exclusively, set read-only, mirror it, optionally anchor the root. | G10: Entry hash; checkpoint | H10: Yes | I10: qb_seclog
A11: ALG-10 | B11: Recompute-from-content verification and inclusion proof | C11: Recompute-from-Content Verifier with Inclusion Proofs | D11: 53 | E11: Log entries; checkpoints | F11: 1. Recompute every entry hash from content. 2. Recompute each Merkle root and compare. 3. Verify checkpoint signatures and chaining. 4. Compare mirrors and anchors. 5. For an entry, emit its sibling path (ceil(log2 n) hashes) as the inclusion proof. | G11: Assurance report; inclusion proof | H11: Yes | I11: qb_seclog
A12: ALG-11 | B12: Frame encode / resynchronizing decode | C12: Framed UFCS-FQL Message Format; Resynchronizing Frame Reader | D12: 55 | E12: Records or media payload | F12: Encode: 1. Compress by payload type. 2. Write the 32-byte header (marker, type, lane, flags, length, sequence). 3. Append metadata, payload, CRC32, optional signature. Decode: 1. Find a marker. 2. Check plausibility, CRC32 and signature. 3. On failure discard and scan to the next marker. | G12: Frames / recovered payloads | H12: Yes | I12: ufcs-transport-lab
... A20: ALG-19 | B20: Tool-call interception and result hashing | C20: MCP Pre-Call and Post-Call Hooks; Tool Result Record Hash | D20: 56, 54, 53 | E20: Tool call; tool result record | F20: 1. Pre-call hook receives the call and may observe, label or refuse. 2. Tool executes. 3. Hash the tool's own result record (SHA-256) and log it. 4. Post-call hook receives the result and the hash; the result record itself is immutable. | G20: Result with record hash; log entries | H20: Yes | I20: qb_mcp, qb_seclog (planned)

Sheet Drawings FIG 1-56
A1: FIG. | B1: Title | C1: Group | D1: Features referencing (count) | E1: Algorithms referencing (count)
A2: 1 | B2: QueryBook system architecture (Prime Directive as Domain 0) | C2: Core platform | D2: =SUMPRODUCT(--ISNUMBER(SEARCH(", "&A2&",",", "&'Feature Registry v69'!$H$2:$H$383&","))) -> 5 | E2: =SUMPRODUCT(--ISNUMBER(SEARCH(", "&A2&",",", "&'Algorithms (v69)'!$D$2:$D$20&","))) -> 0
A3: 2 | B3: Fact Unit — atom, envelope, and content-derived identity | C3: Core platform | D3: =SUMPRODUCT(--ISNUMBER(SEARCH(", "&A3&",",", "&'Feature Registry v69'!$H$2:$H$383&","))) -> 13 | E3: =SUMPRODUCT(--ISNUMBER(SEARCH(", "&A3&",",", "&'Algorithms (v69)'!$D$2:$D$20&","))) -> 0
A4: 3 | B4: Fact-certification authority hierarchy | C4: Core platform | D4: =SUMPRODUCT(--ISNUMBER(SEARCH(", "&A4&",",", "&'Feature Registry v69'!$H$2:$H$383&","))) -> 1 | E4: =SUMPRODUCT(--ISNUMBER(SEARCH(", "&A4&",",", "&'Algorithms (v69)'!$D$2:$D$20&","))) -> 0
A5: 4 | B5: UFCS substrate — three-store architecture | C5: Core platform | D5: =SUMPRODUCT(--ISNUMBER(SEARCH(", "&A5&",",", "&'Feature Registry v69'!$H$2:$H$383&","))) -> 14 | E5: =SUMPRODUCT(--ISNUMBER(SEARCH(", "&A5&",",", "&'Algorithms (v69)'!$D$2:$D$20&","))) -> 0
A6: 5 | B6: Authored tour and exhibition sequencing | C6: Core platform | D6: =SUMPRODUCT(--ISNUMBER(SEARCH(", "&A6&",",", "&'Feature Registry v69'!$H$2:$H$383&","))) -> 3 | E6: =SUMPRODUCT(--ISNUMBER(SEARCH(", "&A6&",",", "&'Algorithms (v69)'!$D$2:$D$20&","))) -> 0
A7: 6 | B7: FQL — joint structure and trust execution | C7: Core platform | D7: =SUMPRODUCT(--ISNUMBER(SEARCH(", "&A7&",",", "&'Feature Registry v69'!$H$2:$H$383&","))) -> 6 | E7: =SUMPRODUCT(--ISNUMBER(SEARCH(", "&A7&",",", "&'Algorithms (v69)'!$D$2:$D$20&","))) -> 1
A8: 7 | B8: Verifying machine-generated text against certified records | C8: Core platform | D8: =SUMPRODUCT(--ISNUMBER(SEARCH(", "&A8&",",", "&'Feature Registry v69'!$H$2:$H$383&","))) -> 6 | E8: =SUMPRODUCT(--ISNUMBER(SEARCH(", "&A8&",",", "&'Algorithms (v69)'!$D$2:$D$20&","))) -> 1
A9: 8 | B9: Federation — cross-boundary re-validation | C9: Core platform | D9: =SUMPRODUCT(--ISNUMBER(SEARCH(", "&A9&",",", "&'Feature Registry v69'!$H$2:$H$383&","))) -> 0 | E9: =SUMPRODUCT(--ISNUMBER(SEARCH(", "&A9&",",", "&'Algorithms (v69)'!$D$2:$D$20&","))) -> 0
A10: 9 | B10: Fact-level erasure by external-key destruction | C10: Core platform | D10: =SUMPRODUCT(--ISNUMBER(SEARCH(", "&A10&",",", "&'Feature Registry v69'!$H$2:$H$383&","))) -> 3 | E10: =SUMPRODUCT(--ISNUMBER(SEARCH(", "&A10&",",", "&'Algorithms (v69)'!$D$2:$D$20&","))) -> 0
A11: 10 | B11: Universal security architecture | C11: Core platform | D11: =SUMPRODUCT(--ISNUMBER(SEARCH(", "&A11&",",", "&'Feature Registry v69'!$H$2:$H$383&","))) -> 4 | E11: =SUMPRODUCT(--ISNUMBER(SEARCH(", "&A11&",",", "&'Algorithms (v69)'!$D$2:$D$20&","))) -> 0
A12: 11 | B12: Universal honeypot saturation and data firehose | C12: Core platform | D12: =SUMPRODUCT(--ISNUMBER(SEARCH(", "&A12&",",", "&'Feature Registry v69'!$H$2:$H$383&","))) -> 1 | E12: =SUMPRODUCT(--ISNUMBER(SEARCH(", "&A12&",",", "&'Algorithms (v69)'!$D$2:$D$20&","))) -> 0
A13: 12 | B13: Deployment topologies over an invariant common layer | C13: Core platform | D13: =SUMPRODUCT(--ISNUMBER(SEARCH(", "&A13&",",", "&'Feature Registry v69'!$H$2:$H$383&","))) -> 5 | E13: =SUMPRODUCT(--ISNUMBER(SEARCH(", "&A13&",",", "&'Algorithms (v69)'!$D$2:$D$20&","))) -> 0
... A57: 56 | B57: Support Interfaces for External Agent-Wrapper Services (Verified Agent Transport and Similar Relays) | C57: Support for agent-wrapper services | D57: =SUMPRODUCT(--ISNUMBER(SEARCH(", "&A57&",",", "&'Feature Registry v69'!$H$2:$H$383&","))) -> 19 | E57: =SUMPRODUCT(--ISNUMBER(SEARCH(", "&A57&",",", "&'Algorithms (v69)'!$D$2:$D$20&","))) -> 6

Sheet Supported External Services
A1: External service | B1: What it is | C1: Where it is described | D1: Status | E1: QueryBook support features used (registry No.) | F1: Count
A2: Verified Agent Transport (VAT) | B2: External agent-wrapper service: a sidecar relay beside an AI agent that verifies the agent's factual claims in transit, binds actions to declared intent, records every frame and verdict, and certifies each session. | C2: Separate provisional application and VAT Feature Registry (querybook/vat/docs) | D2: Specified — not yet built | E2: 364, 365, 366, 367, 368, 369, 370, 371, 372, 373, 374, 375, 376, 377, 378, 379, 380, 381, 382 | F2: 19
A3: Similar agent-wrapper relays (generic) | B3: Any external gateway, proxy or sidecar that checks an AI agent's statements or actions and needs certified facts, a tamper-evident record or session certificates. | C3: Not described in detail; supported through the same registered-caller interfaces | D3: — | E3: 382, 364, 365, 369, 375, 376, 377, 380, 381 | F3: 9
A5: External services are listed for reference only. They are not QueryBook features, are not counted in the Feature Registry, and are not claimed in the QueryBook application; QueryBook claims only the support interfaces (claims 355–357).
